Workbook
Name AirCon: AirConditioner
Name AirCon: AirConditioner
Name AirConditioner: AirConditioner
Name AirConditioner: #REF!
Name AntennaModel: [1]Data!$AI$5:$AI$11
Name AntennaModel: Data!$AI$5:$AI$11
Name Band: Data!$R$5:$R$25
Name Band1: [1]Data!$Q$5:$Q$28
Name Band1: Data!$Q$5:$Q$28
Name Band2: #REF!
Name BTS_MakeModel: #REF!
Name BTSMakeModel: #REF!
Name Current_limit: #REF!
Name EquipmentEnclosure: [1]Data!$M$5:$M$15
Name EquipmentEnclosure: Data!$M$5:$M$15
Name FeederEntry: [1]Data!$K$5:$K$8
Name FeederEntry: Data!$K$5:$K$8
Name Landlord: Data!$X$5:$X$14
Name Landlord1: [1]Data!$X$5:$X$14
Name Landlord1: Data!$X$5:$X$14
Name LeadSite: [1]Data!$L$5:$L$11
Name LeadSite: Data!$L$5:$L$11
Name MER: Data!$H$6:$H$9
Name Mount: #REF!
Name New: #REF!
Name Operator: [1]Data!$S$5:$S$9
Name Operator: Data!$S$5:$S$9
Name Pole: #REF!
Name Quantities: #REF!
Name Quantity: #REF!
Name Rect_Efficency: #REF!
Name Rectifier_Type: #REF!
Name RFCarrier: #REF!
Name Shelter_Material: #REF!
Name ShelterMaterial: #REF!
Name SiteType: #REF!
Name StructureType: [1]Data!$D$5:$D$11
Name StructureType: Data!$D$5:$D$11
Name TechBand: [1]Data!$AL$5:$AL$26
Name TechBand: Data!$AL$5:$AL$26
Name Technology: #REF!
Name Transmission: #REF!
Name TransmissionMake: #REF!
Name TransmissionType: #REF!
Name TXMakeModel: #REF!
Name Vendor: #REF!
Name VendorDC: #REF!
Name WHSRating: #REF!
Name YesNo: [1]Data!$A$5:$A$7
Name YesNo: Data!$A$5:$A$7
Name YesNoNA: #REF!
Name YesNoPassFail: #REF!

Sheet Cover Sheet
B2: ='Document Control'!B2 -> OM34440 Optus Site Feasibility Report | I2: V | J2: ='Document Control'!C3 -> 5 | K2: Cover Sheet
B3: Site No. | D3: H8097 | G3: Site Name | J3: Austins Ferry
C5: NOTE: It is mandatory to complete the Cover Sheet and Site Access sheet for all projects
C6: Project | G6: OHOB eJV 5G upgrade
C8: Description of proposed works | G8: OHOB eJV 5G upgrade
C9: NOTE: Always click the Unhide Worksheets button prior to pressing any alternative button
C11: JV Site ID | G11: JH3038
C13: Optus Site Number | G13: H8097 | M13: Lead Operator | Q13: Optus
C15: Optus Site Name | G15: Austins Ferry | M15: Voda Site Name | Q15: Austins Ferry - V
C17: Optus Site Code | G17: 77FE | M17: Voda Site ID | Q17: 3819
C20: Document Approval
G22: Signature | N22: Name | T22: Date
C23: Lead PM
C25: Lead RF
C27: Non Lead RF
C29: Lead Network Engineer
C31: Has the Site Feasibility been fully approved ?
C33: Completed Tabs
C35: NOTE: Automatically populates dependant on your first question answer on each tab
C37: Feasibility Site Acquisition | J37: Complete | M37: Install & Commission Feasibility | T37: Complete
C38: Cover Sheet | J38: =G49 -> Yes | M38: BTS | T38: =BTS!S7 -> Yes
C39: Site Access | J39: ='Site Access'!T7 -> Yes | M39: DC | T39: =DC!S7 -> Yes
C40: Property | J40: =Property!K7 -> Yes | M40: TX | T40: =TX!S7 -> N/A
C41: Planning | J41: =Planning!K7 -> Yes | M41: Floor Layout | T41: ='Floor Layout'!S7 -> Yes
C42: Design | J42: =Design!K7 -> Yes | M42: Antenna System | T42: =#REF! -> #REF!
M43: Photos | T43: =Photos!S7 -> Yes
C49: Page Completed | G49: Yes | M49: By Whom | Q49: SARAVANAN S
C51: Company | G51: ALL TELECOS | M51: Date | Q51: 45913

Sheet IC Works Summary
B2: ='Document Control'!B2 -> OM34440 Optus Site Feasibility Report | F2: V | G2: ='Document Control'!C3 -> 5 | H2: Feasibility Score of Works Summary
B3: Site No. | D3: ='Cover Sheet'!G13 -> H8097 | F3: Site Name | H3: ='Cover Sheet'!G15 -> Austins Ferry
C5: NOTE: All Summaries are automatically imported from the Scope of Works Summary at the bottom of each tab
C7: Construction Summary
C8: =Design!C108 -> 1. ANTENNA SCOPE: SHARED : REPLACE EXISTING eJV 12P HUAWEI ASI4517R1 PANEL ANTENNAS (3 OFF) WITH NEW eJV 16P COMMSCOPE RRVV2VV-6533D-R8 PANEL ANTENNAS (1 OFF PER SECTOR) (FOR SECTOR 11-J, 21-J, & 31-J) ON NEW ANTENNA MOUNT CONNECTED TO NEW COLLAR MOUNT OPTUS : INSTALL NEW OPTUS ERICSSON AIR3268 B78Y (NR35) ANTENNAS (1 OFF PER SECTOR) (FOR SECTOR 12-O, 22-O, & 32-O) ON NEW ANTENNA MOUNT CONNECTED TO NEW COLLAR MOUNT VODAFONE : INSTALL NEW VODAFONE NOKIA AVQL (NR36) ANTENNAS (1 OFF PER SECTOR) (FOR SECTOR 13-V, 23-V, & 33-V) (BELOW OPTUS AAU) ON NEW ANTENNA MOUNT CONNECTED TO NEW COLLAR MOUNT 2. RRU SCOPE: OPTUS : REMOVE EXISTING OPTUS HUAWEI RRU3262 (L7) (3 OFF), RRU3936 (U9) (3 OFF), RRU3971 (L18) (3 OFF), RRU3971 (L21) (3 OFF) & RRU3281 (L26) (3 OFF). INSTALL NEW OPTUS ERICSSON RRU4480 (L7/NL9) (1 OFF PER SECTOR, 3 OFF TOTAL), RRU4466 (L18/NL21/L26) (1 OFF PER SECTOR, 3 OFF TOTAL) AND FUTURE RRU (2 OFF PER SECTOR, 6 OFF TOTAL) ON NEW RRU MOUNT CONNECTED TO NEW COLLAR MOUNT VODAFONE: REMOVE EXISTING VODAFONE HUAWEI RRU3952 (L850) (3 OFF), RRU3953 (U9) (3 OFF), RRU3971 (L18) (3 OFF) & RRU3971 (L21) (3 OFF). INSTALL NEW VODAFONE NOKIA RRU AHPB (N7) (1 OFF PER SECTOR, 3 OFF TOTAL), AHCA (L850) (1 OFF PER SECTOR, 3 OFF TOTAL) AND AHEGG (18/21) (2 OFF PER SECTOR, 6 OFF TOTAL) ON NEW RRU MOUNT CONNECTED TO NEW COLLAR MOUNT 3. COMBINER & MHA SCOPE: OPTUS : REMOVE EXISTING OPTUS COMBINERS COM2a (E12F13P25) (3 OFF) & COM3 (E16V90P56) (6 OFF). INSTALL NEW OPTUS REJ FILTER (E14V00P21) (1 OFF PER SECTOR, 3 OFF TOTAL) BEHIND NEW PANEL ANTENNAS ON NEW MOUNT VODAFONE: REMOVE EXISTING VODAFONE COMBINERS COM2 (E12F03P18) (3 OFF) & COM4 (E14F05P17) (6 OFF). INSTALL NEW VODAFONE COMBINER COM2g (E14F06P81) (1 OFF PER SECTOR, 3 OFF TOTAL) BEHIND NEW PANEL ANTENNAS ON NEW MOUNT 4. HYRBID SCOPE : OPTUS: REUSE EXISTING OPTUS H&S 9/18 HYBRID CABLE (1 OFF) (LENGTH: 40m) AND SHARED H&S 9/18 HYBRID CABLE (1 OFF) (LENGTH: 40m) TO BE ALLOCATED TO OPTUS TO RUN IN EXISTING OPTUS 450mm WIDE CABLE LADDER VODAFONE: REUSE EXISTING VODAFONE H&S 9/18 HYBRID CABLE (1 OFF) (LENGTH: 40m) AND INSTALL NEW H&S 9/18 (10mm2) HYBRID CABLES (1 OFF) (LENGTH: 40m) FOR VODAFONE TO RUN IN EXISTING OPTUS 450mm WIDE CABLE LADDER 5. GPS: OPTUS : REPLACE EXISTING OPTUS GPS ANTENNA (1 OFF) WITH NEW OPTUS ERICSSON GNSS GPS ANTENNA (1 OFF) ON THE TOP OF SHELTER WALL VODAFONE: INSTALL NEW VODAFONE NOKIA AYGE GPS ANTENNA (1 OFF) ON THE TOP OF SHELTER WALL. ENSURE MIN. 500mm HORIZONTAL SEPERATION FROM OTHER GPS ANTENNA
C17: BTS Summary
C18: =BTS!C60 -> OPTUS NOTES: 1. REMOVE EXISTING OPTUS HUAWEI BBU AND DCDU FROM THE RACK AT G001F04. 2. INSTALL NEW 1 x ERICSSON BBU6672 FOR L7/NL9/L18/NL21/L26/NR35 IN RACK AT G001F04. 3. INSTALL NEW DCDU (1 OFF) TO POWER UP ERICSSON BBUs IN RACK AT G001F04. 4. ALL EXTERNAL ALARMS (ENVIRONMENTAL ETC) TO BE MIGRATED FROM UMTS BBU TO LTE/5G BBU, AS PER OPTUS STANDARDS, INCLUDING OM36991 RAN EQUIPMENT I&C STANDARDS. 5. ALL 3G CONTROLLED RET'S TO BE MIGRATED TO 4G/5G AS REQUIRED, ACCORDING TO OPTUS STANDARDS, INCLUDING OM38040 MIMO PORT PLUMBING BTS RET CONTROL DEPLOYMENT. 6. REMOVE ANY ON-SITE CCU'S AND CONVERT CCU CONTROLLED MHA'S TO BTS CONTROLLED 7. EXISTING KRONE PANEL TO BE UPGRADED TO RJ45 PATCH PANEL. INSTALL 1 x 6610 FOR PSU ALARM AT G000.F02. iDCDP NOTES: 8. REUSE EXISTING OPTUS 22-WAY LENMIC iDCDP (1 OFF) IN RACK AT G001F05. AND SWAP CBs ON PSU AND iDCDP AS PER LATEST GUIDELINE. VODAFONE NOTES: 9. REMOVE EXISTING VODAFONE HUAWEI BBU AND DCDU FROM THE RACK AT G001F02. 10. INSTALL NEW NOKIA AIRSCALE/AMID CHASIS 1 OFF WITH SUITABLE BB CARDS AS PER EBP IN RACK AT G001F02. 11. NOKIA AIRSCALE SHALL BE POWER UP VIA VODAFONE PSU IN RACK AT G000F04. 12. NOKIA TX ROUTER TO BE RELOACTED FROM RU7 TO RU18 OR HIGHER POSTION AT G000F02. iDCDP NOTES: 13. REUSE EXISTING VODAFONE 22-WAY LENMIC iDCDP (1 OFF) IN RACK AT G001F05. AND SWAP CBs ON PSU AND iDCDP AS PER LATEST GUIDELINE.
C27: DC Summary
C28: =DC!C74 -> OPTUS DC POWER UPGRADE: 1. REMOVE EXISTING OPTUS HUAWEI PSU (1 OFF) WITH EXISTING 3kW RECTIFIERS (6 OFF) AND LPFG12-100S BATTERY STRINGS (5 OFF) FROM THE RACK AT G000F03. 2. INSTALL NEW OPTUS 27kW VERTIV PSU WITH NEW 3kW RECTIFIERS (6 OFF) AT G000F03. 3. INSTALL NEW LFeLi-48100ZN BATTERIES (5 OFF) IN RACK AT G000F03. 4. REPLACE EXISTING 32A 1P CB (3 OFF) WITH NEW 40A 1P CB (3 OFF) FOR OPTUS PSU ON THE DISTRIBUTION BOARD. 5. OPTUS POWER TOOL V12.7 APPROVED. 6. DIVERSIFY Tx FEEDS OVER 2 PSUs. APDP FEED A ON OPTUS PSU-1-O. FEED B ON VODAFONE PSU-2-V. VODAFONE DC POWER UPGRADE: 7. REMOVE EXISTING VODAFONE HUAWEI PSU (1 OFF) WITH EXISTING 3kW RECTIFIERS (6 OFF) AND LPFG12-100S BATTERY STRINGS (5 OFF) FROM THE RACK AT G000F04. 8. INSTALL NEW VODAFONE 27kW VERTIV PSU WITH NEW 3kW RECTIFIERS (6 OFF) AT G000F04. 9. INSTALL NEW LFeLi-48100ZN BATTERIES (5 OFF) IN RACK AT G000F04. 10. REPLACE EXISTING 32A 1P CB (3 OFF) WITH NEW 40A 1P CB (3 OFF) FOR VODAFONE PSU ON THE DISTRIBUTION BOARD.
C37: TX Summary
C38: =TX!C184 -> 0
C48: Floor Layout Summary
C49: ='Floor Layout'!C44 -> OPTUS NOTES: 1. REMOVE EXISTING OPTUS HUAWEI BBU AND DCDU FROM THE RACK AT G001F04. 2. INSTALL NEW 1 x ERICSSON BBU6672 FOR L7/NL9/L18/NL21/L26/NR35 IN RACK AT G001F04. 3. INSTALL NEW DCDU (1 OFF) TO POWER UP ERICSSON BBUs IN RACK AT G001F04. 4. ALL EXTERNAL ALARMS (ENVIRONMENTAL ETC) TO BE MIGRATED FROM UMTS BBU TO LTE/5G BBU, AS PER OPTUS STANDARDS, INCLUDING OM36991 RAN EQUIPMENT I&C STANDARDS. 5. ALL 3G CONTROLLED RET'S TO BE MIGRATED TO 4G/5G AS REQUIRED, ACCORDING TO OPTUS STANDARDS, INCLUDING OM38040 MIMO PORT PLUMBING BTS RET CONTROL DEPLOYMENT. 6. REMOVE ANY ON-SITE CCU'S AND CONVERT CCU CONTROLLED MHA'S TO BTS CONTROLLED 7. EXISTING KRONE PANEL TO BE UPGRADED TO RJ45 PATCH PANEL. INSTALL 1 x 6610 FOR PSU ALARM AT G000.F02. iDCDP NOTES: 8. REUSE EXISTING OPTUS 22-WAY LENMIC iDCDP (1 OFF) IN RACK AT G001F05. AND SWAP CBs ON PSU AND iDCDP AS PER LATEST GUIDELINE. HYBRID CABLE NOTES: 9. REUSE EXISTING OPTUS H&S 9/18 HYBRID CABLE (1 OFF) (LENGTH: 40m) AND SHARED H&S 9/18 HYBRID CABLE (1 OFF) (LENGTH: 40m) DC POWER UPGRADE: 10. REMOVE EXISTING OPTUS HUAWEI PSU (1 OFF) WITH EXISTING 3kW RECTIFIERS (6 OFF) AND LPFG12-100S BATTERY STRINGS (5 OFF) FROM THE RACK AT G000F03. 11. INSTALL NEW OPTUS 27kW VERTIV PSU WITH NEW 3kW RECTIFIERS (6 OFF) AT G000F03. 12. INSTALL NEW LFeLi-48100ZN BATTERIES (5 OFF) IN RACK AT G000F03. 13. REPLACE EXISTING 32A 1P CB (3 OFF) WITH NEW 40A 1P CB (3 OFF) FOR OPTUS PSU ON THE DISTRIBUTION BOARD. 14. OPTUS POWER TOOL V12.7 APPROVED. 15. DIVERSIFY Tx FEEDS OVER 2 PSUs. APDP FEED A ON OPTUS PSU-1-O. FEED B ON VODAFONE PSU-2-V. AC POWER UPGRADE: 16. EXISTING OPTUS 50A THREE PHASE POWER SUPPLY IS SUFFICIENT FOR THE PROPOSED UPGRADE. VODAFONE NOTES: 17. REMOVE EXISTING VODAFONE HUAWEI BBU AND DCDU FROM THE RACK AT G001F02. 18. INSTALL NEW NOKIA AIRSCALE/AMID CHASIS 1 OFF WITH SUITABLE BB CARDS AS PER EBP IN RACK AT G001F02. 19. NOKIA AIRSCALE SHALL BE POWER UP VIA VODAFONE PSU IN RACK AT G000F04. 20. NOKIA TX ROUTER TO BE RELOACTED FROM RU7 TO RU18 OR HIGHER POSTION AT G000F02. iDCDP NOTES: 21. REUSE EXISTING VODAFONE 22-WAY LENMIC iDCDP (1 OFF) IN RACK AT G001F05. AND SWAP CBs ON PSU AND iDCDP AS PER LATEST GUIDELINE. HYBRID CABLE NOTES: 22. REUSE EXISTING VODAFONE H&S 9/18 HYBRID CABLE (1 OFF) (LENGTH: 40m) AND INSTALL NEW H&S 9/18 (10mm2) HYBRID CABLES (1 OFF) (LENGTH: 40m) DC POWER UPGRADE: 23. REMOVE EXISTING VODAFONE HUAWEI PSU (1 OFF) WITH EXISTING 3kW RECTIFIERS (6 OFF) AND LPFG12-100S BATTERY STRINGS (5 OFF) FROM THE RACK AT G000F04. 24. INSTALL NEW VODAFONE 27kW VERTIV PSU WITH NEW 3kW RECTIFIERS (6 OFF) AT G000F04. 25. INSTALL NEW LFeLi-48100ZN BATTERIES (5 OFF) IN RACK AT G000F04. 26. REPLACE EXISTING 32A 1P CB (3 OFF) WITH NEW 40A 1P CB (3 OFF) FOR VODAFONE PSU ON THE DISTRIBUTION BOARD.
C59: Antenna System Summary
C60: =#REF! -> #REF!

Sheet Site Access
B2: ='Document Control'!B2 -> OM34440 Optus Site Feasibility Report | I2: V | J2: ='Document Control'!C3 -> 5 | K2: Site Access Details
B3: Site No. | D3: ='Cover Sheet'!G13 -> H8097 | G3: Site Name | J3: ='Cover Sheet'!G15 -> Austins Ferry
C5: NOTE: If you answer 'No' to the below question you are not required to complete any other information on this page, unless under instruction from Optus or performing a feasibility study.
C7: Are you required to perform a feasibility study on the site? | T7: Yes
C9: Details
C12: JV Site Number | G12: ='Cover Sheet'!G11:K11 -> JH3038
C14: Optus Site Name | G14: ='Cover Sheet'!G15 -> Austins Ferry
O15: Pink Cells will automatically be updated from information entered on the Cover Sheet
C16: Optus Site Number | G16: ='Cover Sheet'!G13 -> H8097
C18: Optus Site Code | G18: ='Cover Sheet'!G17:K17 -> 77FE
C20: Voda Site Name | G20: ='Cover Sheet'!Q15 -> Austins Ferry - V
C22: Voda Site ID | G22: ='Cover Sheet'!Q17 -> 3819
C24: Site Address | G24: 2 Plan 158154 Wakehurst Rd, AUSTINS FERRY TAS 7011
C27: Postcode | G27: 7011
C29: Longitude JDA94 | G29: 147.24512 | M29: Latitude JDA94 | O29: Latitude | Q29: -42.77817
C31: Special Access Instructions
C32: ENTER POIMENA RESERVE FROM WAKEHURST ROAD AND TRAVEL TO UPPER CARPARK. OPTUS TO DAISY CHAIN LOCK INTO GATE TO GAIN ACCESS TO GATE.
C33: TRAVEL UP EXISTING ACCESS TRACK TO TELSTRA FACILITY.
C34: (NOTE: ACCESS TRACK IS ON/NEXT TO FRISBEE GOLF COURSE, CAUTION SHOULD BE TAKEN)
C36: Site Owner | P36: Other
C38: Details | E38: Glenorchy City Council
C40: Structure Type | P40: Monopole
C42: Details | E42: 27m HIGH CONCRETE MONOPOLE (SR3-BM27-585).
C44: Structure Owner | P44: Optus
C46: Details | E46: Optus
C48: Equipment Enclosure Type | P48: Sandwich Panel Shelter
C50: Details | E50: OPTUS ZONECOOL C3 (3.0m x 2.5m) EQUIPMENT SHELTER.
C52: Greenfield Site | P52: No
C54: Details
C56: Site Access
C58: (Add specific key, Property Manager, 24/7 access to the Details section when required)
C60: Is a special permit required for access? | O60: (If yes complete the details below) | P60: No
C62: Details
C65: Are access times restricted? | P65: No
C67: Details
C69: Is a Security Escort required? | P69: No
C71: Details
C73: Is a Special key required? | P73: Yes
C75: Details | E75: OPTUS TO DAISY CHAIN LOCK INTO GATE TO GAIN ACCESS TO GATE.
C77: Is an induction required | P77: No
...

Sheet Property
B2: ='Document Control'!B2 -> OM34440 Optus Site Feasibility Report | F2: V | G2: ='Document Control'!C3 -> 5 | H2: Property
B3: Site No. | D3: ='Cover Sheet'!G13 -> H8097 | F3: Site Name | H3: ='Cover Sheet'!G15 -> Austins Ferry
C5: NOTE: If you answer 'No' to the below question you are not required to complete any other information on this page, unless under instruction from Optus or performing a feasibility study.
C7: Are you required to perform a feasibility study on the site? | K7: Yes
C9: Details
C11: Do both operators have separate ground/rooftop leases ? | K11: Yes
C13: Details | D13: Lease with Glenorchy City Council
C16: Landlord - Ground Lease? | K16: Local Council
C18: Details | D18: Lease with Glenorchy City Council
C21: Landlord - Structure Lease? | K21: Optus
C23: Details | D23: Optus owned tower
C27: Is this a Greenfield Site ? | K27: No
C29: Details | D29: Upgrade 5G (EJV OH)
C33: Property Tenure Considerations
C35: Lease or Licence | F35: 1. Tower licence with Amplitel 2. Ground Lease with Glenorchy City Council
C36: Lessor or Licensor | F36: Lessor
C37: Co-locate / Co-Site (e.g. Crown Castle, Telstra, etc) | F37: co-site to Telstra
C38: Type & Structure (e.g. tower, rooftop, reservoir, etc) | F38: Monopole
C39: Tenure | D39: Period | F39: 01.01.2022 to 31.05.2036 (14 years 5 months)
D40: Commencement | F40: 01.01.2022
D41: Remaining | F41: 10 years and 8 months
D42: Current Rental & Escalation | F42: 1.Tower licence fee - as per Optus/Amplitel MAA 2. Ground lease - $16,390.91 + 3% Esc.
D43: Special Conditions | F43: Yes -Market rent review every 5 years
D44: Sub-Lease | F44: Optus may sublet the premises upon written notice to the Lessor- Refer to clause 12.4
D45: Renegotiation Required | F45: N
C46: Rental Increase expected? Y/N | F46: N
C47: If yes, please provide estimated increase
C48: Lease / licence area variation requirements | F48: n/a
C49: Limitations on expansion of lease area | F49: No
C50: Consent requirements for additional equipment | F50: CNTBUW - Refer to clause 8.2
C51: Consent required for sub-lease / licence | F51: Optus may sublet the premises upon written notice to the Lessor- Refer to clause 12.4
C52: Other conditions pertaining to site (e.g. access, security) | F52: AOR - Refer to Clause 5.2 & Clause 6
C53: Other Carrier Implications | F53: Co-site notice to Telstra
C54: Does Lease/Licence contain a redevelopment clause? - Y/N | F54: N
C55: If Yes, will redevelopment be invoked in the near future? | F55: n/a
C56: B-end acquisition works required? - Y/N If Yes, perform property tenure considerations for B-end) | F56: N
C58: Property Risk Assessment
C60: Details | D60: Optus owned structure. Works require council's consent - CNTBUW. Site access is through another lot also owned by council. Co-site notice will be required for Telstra in Phase 2.
C65: Page Completed | E65: Yes | H65: By Whom | I65: Akhil Davuluri
C67: Company | E67: CPS Tech | H67: Date | I67: 16.09.25

Sheet Planning
B2: ='Document Control'!B2 -> OM34440 Optus Site Feasibility Report | F2: V | G2: ='Document Control'!C3 -> 5 | H2: Planning
B3: Site No. | D3: ='Cover Sheet'!G13 -> H8097 | F3: Site Name | H3: ='Cover Sheet'!G15 -> Austins Ferry
C5: NOTE: If you answer 'No' to the below question you are not required to complete any other information on this page, unless under instruction from Optus or performing a feasibility study.
C7: Are you required to perform a feasibility study on the site? | K7: Yes
C9: Details
C11: Environmental Planning Considerations
C13: 25% volume increase compromised ? | F13: TBC
C14: Adjoining Council notification | F14: No
C15: Area (Part 2 of LIFD) | F15: Residential
C16: Area of Environmental Significance (ES) | F16: No
C17: Associated Timeframe | F17: 2-4 weeks
C18: CA Deployment Category | F18: DC7
C19: Community Sensitivity (TLM) | F19: Amber
C20: Community Sensitivity Comments | F20: Previous deployments received no comments or submissions. While properties to the north may have clearer views due to reduced vegetation, the upgrade will have minimal visual impact as it does not increase the structure’s height or volume.
C21: General Site Area Comments | F21: The site is located within an open space/reserve area surrounded by residential suburbs. Due to its elevated position and surrounding vegetation, visual impacts are minimal. The land is subject to a bushfire overlay, which should be considered during further due diligence; however, this is unlikely to affect the upgrade as both the monopole and equipment shelter are existing structures
C22: Heritage / Environmental Comments | F22: No
C23: Local Government Area (LGA) e.g. shire, council etc | F23: Glenorchy City Counil
C24: Low Impact site | F24: Yes
... C31: Zone | F31: Open Space
C37: Environmental Risk Assessment
C39: Details
C40: The land is within an open space zone, and is subject to a Bushfire-prone overlay and priority vegetation overlay. Given that the scope of works is for an upgrade of existing panel antennas as well as ancillary equipment, and the fact there will be no increase in height to the lattice tower, nor any new or replacement of equipment shelters, these overlays should not impact the low impact status of the proposal.
C43: Recommended Strategy
C45: Details
C46: Deployment Code 7 notification, Letters to Glenorchy Council, State & Fed MP, IAP letters and a Sign on site, estimated time 12 business days
C50: Page Completed | E50: Yes | H50: By Whom | I50: Tiana Sinopoli
C52: Company | E52: CPS Technology & Infrastrucutre | H52: Date | I52: 45916

Sheet Design
B2: ='Document Control'!B2 -> OM34440 Optus Site Feasibility Report | F2: V | G2: ='Document Control'!C3 -> 5 | H2: Design
B3: Site No. | D3: ='Cover Sheet'!G13 -> H8097 | F3: Site Name | H3: ='Cover Sheet'!G15 -> Austins Ferry
C5: NOTE: If you answer 'No' to the below question you are not required to complete any other information on this page, unless under instruction from Optus or performing a feasibility study.
C7: Are you required to perform a feasibility study on the site? | K7: Yes
C9: Details
C11: Structure Type
C13: Structure Type | E13: ='Site Access'!P40 -> Monopole
C14: Structure Owner | E14: ='Site Access'!P44 -> Optus
C15: Manufacturer & Model | E15: ROCLA CONCRETE MONOPOLE & SR3-BM27-585
C16: Structure Height | E16: 27m
C17: Antenna Height | E17: 23.10m & 24.10m
C18: Structure Loading | E18: 0.99
C19: Foundation Loading | E19: 0.99
C21: Details | D21: Refer to Pole certificate 292920_1 by Civilmart
C24: Condition of Existing Mounts & Sundry Supports
C26: Sector | D26: Mount | E26: Type | F26: Length | G26: Describe Works Required to Upgrade for Target Antenna Solution
C27: 1 | D27: New Antenna mount | E27: CHS | F27: 2.7m | G27: SHARED : REPLACE EXISTING eJV 12P HUAWEI ASI4517R1 PANEL ANTENNAS (3 OFF) WITH NEW eJV 16P COMMSCOPE RRVV2VV-6533D-R8 PANEL ANTENNAS (1 OFF PER SECTOR) (FOR SECTOR 11-J, 21-J, & 31-J) ON NEW ANTENNA MOUNT CONNECTED TO NEW COLLAR MOUNT OPTUS : INSTALL NEW OPTUS ERICSSON AIR3268 B78Y (NR35) ANTENNAS (1 OFF PER SECTOR) (FOR SECTOR 12-O, 22-O, & 32-O) ON NEW ANTENNA MOUNT CONNECTED TO NEW COLLAR MOUNT VODAFONE : INSTALL NEW VODAFONE NOKIA AVQL (NR36) ANTENNAS (1 OFF PER SECTOR) (FOR SECTOR 13-V, 23-V, & 33-V) (BELOW OPTUS AAU) ON NEW ANTENNA MOUNT CONNECTED TO NEW COLLAR MOUNT
C28: 2 | D28: New Antenna mount | E28: CHS | F28: 2.7m
C29: 3 | D29: New Antenna mount | E29: CHS | F29: 2.7m
C32: Details
C35: Cable Ladder
C37: Describe existing cable ladder, size mounting method, etc
C38: Sector 1 | D38: ALL CABLES TO BE RUN IN EXISTING 450 WIDE ELEVATED CABLE LADDER
C39: Sector 2
C40: Sector 3
C41: Sector 4
C43: Describe works required to upgrade for Target Antenna Solution
C44: Sector 1 | D44: OPTUS: REUSE EXISTING OPTUS H&S 9/18 HYBRID CABLE (1 OFF) (LENGTH: 40m) AND SHARED H&S 9/18 HYBRID CABLE (1 OFF) (LENGTH: 40m) TO BE ALLOCATED TO OPTUS TO RUN IN EXISTING OPTUS 450mm WIDE CABLE LADDER VODAFONE: REUSE EXISTING VODAFONE H&S 9/18 HYBRID CABLE (1 OFF) (LENGTH: 40m) AND INSTALL NEW H&S 9/18 (10mm2) HYBRID CABLES (1 OFF) (LENGTH: 40m) FOR VODAFONE TO RUN IN EXISTING OPTUS 450mm WIDE CABLE LADDER
C45: Sector 2
C46: Sector 3
C47: Sector 4
C49: Details
C52: Other Carriers On Site (Mark X in relevant boxes)
C54: Telstra | D54: 3GIS | E54: Voda | G54: Others
C55: X | E55: X
C57: Details
C60: Shelter Fit Out
C62: Shelter/Cabinet type & details | F62: ='Site Access'!P48 -> Sandwich Panel Shelter
C63: Is there any floor space available | F63: YES
C64: Does the existing Gland Window have sufficient space for new feeders | F64: YES
...

Sheet BTS
B2: ='Document Control'!B2 -> OM34440 Optus Site Feasibility Report | I2: V | J2: ='Document Control'!C3 -> 5 | K2: BTS Details
B3: Site No. | D3: ='Cover Sheet'!G13 -> H8097 | G3: Site Name | J3: ='Cover Sheet'!G15 -> Austins Ferry
C5: NOTE: If you answer 'No' to the below question you are not required to complete any other information on this page, unless under instruction from Optus or performing a feasibility study.
C7: Are you performing a feasibility on the BTS system? | S7: Yes
C9: Details
C12: Existing BTS Technologies
C14: Suite Number | F14: Operator | H14: Vendor | J14: Cabinet | L14: Band | N14: Technology | P14: TX Type | S14: BTS Recovery Required | U14: Combiner Used
C15: G001F04 | F15: Optus | H15: ICS | J15: RACK | L15: 7/18/21/26 | N15: LTE | P15: IP | S15: Yes | U15: Yes
C16: G001F04 | F16: Optus | H16: ICS | J16: RACK | L16: 9/21 | N16: UMTS | P16: IP | S16: Yes | U16: Yes
C17: G001F02 | F17: Voda | H17: ICS | J17: RACK | L17: 85/18/21 | N17: LTE | P17: IP | S17: Yes | U17: Yes
C18: G001F02 | F18: Voda | H18: ICS | J18: RACK | L18: 9 | N18: UMTS | P18: IP | S18: Yes | U18: Yes
C23: Details
C26: Which BTS is monitoring Environmental alarms? | S26: Other
C28: Details | E28: EXISTING Tx MER RACK
C30: Are two footprints available for each carrier? | N30: No | S30: Yes
C32: Details | E32: Spare Racks available
C34: Are you installing a BTS/s into an MER Rack? | N34: No | S34: Yes
C36: Details
C39: Proposed BTS Technologies
C41: Suite Number | F41: Operator | H41: Vendor | J41: Cabinet | L41: Band | N41: Technology | P41: TX Type | S41: Floor space Recovered | U41: Combiner Used
C42: G001F04 | F42: Optus | H42: ICS | J42: RACK | L42: 7/18/26 | N42: LTE | P42: IP | S42: N/A | U42: No
C43: G001F04 | F43: Optus | H43: ICS | J43: RACK | L43: 9/21 | N43: LTE / NR | P43: IP | S43: N/A | U43: No
C44: G001F04 | F44: Optus | H44: ICS | J44: RACK | L44: 35 | N44: NR | P44: IP | S44: N/A | U44: No
C45: G001F02 | F45: Voda | H45: ICS | J45: RACK | L45: .85/18/21 | N45: LTE | P45: IP | S45: N/A | U45: Yes
C46: G001F02 | F46: Voda | H46: ICS | J46: RACK | L46: 7/36 | N46: NR | P46: IP | S46: N/A | U46: Yes
C50: Details
C52: Which BTS will be monitoring Environmental alarms? | S52: Other
C54: Which BTS technology is proposed to provide RET control? | S54: Other
C56: Suite | E56: G001F04
C58: Fill in the Scope of Works Summary box below with as much details as possible relating to the proposed BTS upgrade site works.
C60: OPTUS NOTES: 1. REMOVE EXISTING OPTUS HUAWEI BBU AND DCDU FROM THE RACK AT G001F04. 2. INSTALL NEW 1 x ERICSSON BBU6672 FOR L7/NL9/L18/NL21/L26/NR35 IN RACK AT G001F04. 3. INSTALL NEW DCDU (1 OFF) TO POWER UP ERICSSON BBUs IN RACK AT G001F04. 4. ALL EXTERNAL ALARMS (ENVIRONMENTAL ETC) TO BE MIGRATED FROM UMTS BBU TO LTE/5G BBU, AS PER OPTUS STANDARDS, INCLUDING OM36991 RAN EQUIPMENT I&C STANDARDS. 5. ALL 3G CONTROLLED RET'S TO BE MIGRATED TO 4G/5G AS REQUIRED, ACCORDING TO OPTUS STANDARDS, INCLUDING OM38040 MIMO PORT PLUMBING BTS RET CONTROL DEPLOYMENT. 6. REMOVE ANY ON-SITE CCU'S AND CONVERT CCU CONTROLLED MHA'S TO BTS CONTROLLED 7. EXISTING KRONE PANEL TO BE UPGRADED TO RJ45 PATCH PANEL. INSTALL 1 x 6610 FOR PSU ALARM AT G000.F02. iDCDP NOTES: 8. REUSE EXISTING OPTUS 22-WAY LENMIC iDCDP (1 OFF) IN RACK AT G001F05. AND SWAP CBs ON PSU AND iDCDP AS PER LATEST GUIDELINE. VODAFONE NOTES: 9. REMOVE EXISTING VODAFONE HUAWEI BBU AND DCDU FROM THE RACK AT G001F02. 10. INSTALL NEW NOKIA AIRSCALE/AMID CHASIS 1 OFF WITH SUITABLE BB CARDS AS PER EBP IN RACK AT G001F02. 11. NOKIA AIRSCALE SHALL BE POWER UP VIA VODAFONE PSU IN RACK AT G000F04. 12. NOKIA TX ROUTER TO BE RELOACTED FROM RU7 TO RU18 OR HIGHER POSTION AT G000F02. iDCDP NOTES: 13. REUSE EXISTING VODAFONE 22-WAY LENMIC iDCDP (1 OFF) IN RACK AT G001F05. AND SWAP CBs ON PSU AND iDCDP AS PER LATEST GUIDELINE.
C66: Information will be automatically generated to the IC Works Summary tab
C68: Page Completed | H68: Yes | M68: By Whom | Q68: SARAVANAN S
C70: Company | H70: ALL TELECOS | M70: Date | Q70: 45913

Sheet DC
B2: ='Document Control'!B2 -> OM34440 Optus Site Feasibility Report | I2: V | J2: ='Document Control'!C3 -> 5 | K2: DC Supply Details | Y2: ='Document Control'!B2 -> OM34440 Optus Site Feasibility Report | AC2: V | AD2: ='Document Control'!C3 -> 5 | AE2: Power Calculations Summary Report
B3: Site No. | D3: ='Cover Sheet'!G13 -> H8097 | G3: Site Name | J3: ='Cover Sheet'!G15 -> Austins Ferry | Y3: Site No. | AA3: ='Cover Sheet'!G15 -> Austins Ferry | AC3: Site Name | AF3: ='Cover Sheet'!G13 -> H8097
C5: NOTE: If you answer 'No' to the below question you are not required to complete any other information on this page, unless under instruction from Optus or performing a feasibility study. | Y5: Power Calculations Summary Report can be generated with OM38347 Optus Power Calculator. Once the report is generated, copy the report as instructed in OM38347, Click the Red Box below and paste (ctrl-v) the report below.
C7: Are you performing a feasibility on the DC system? | S7: Yes
C9: Details | Y9: PASTE
C12: NOTE: Refer to the DC Power Calculator for equipment current draw and final DC supply requirements. EJV sites require two separate power supplies one for carrier.
C13: Existing DC Solution
C15: Suite Number | F15: Operator | H15: Vendor | L15: Battery String Quantity | N15: Rectifier Quantity | P15: Current Draw Amps | R15: DC Recovery Required
C16: G000FO3 | F16: Optus | H16: HUAWEI | L16: 5 | N16: 6 | P16: - | R16: Yes
C17: G000FO4 | F17: Voda | H17: HUAWEI | L17: 5 | N17: 6 | P17: - | R17: Yes
C23: Proposed DC Solution
C25: Suite Number | F25: Operator | H25: Vendor | L25: Battery String Quantity | N25: Rectifier Quantity | P25: Current Draw Amps | R25: DC Recovery Required
C26: G000FO3 | F26: Optus | H26: VERTIV | L26: 5 | N26: 6 | P26: - | R26: NA
C27: G000FO4 | F27: Voda | H27: VERTIV | L27: 5 | N27: 6 | P27: - | R27: NA
C32: Does an upgrade need to be performed? | S32: Yes
C34: Details | E34: OPTUS DC POWER UPGRADE: 1. REMOVE EXISTING OPTUS HUAWEI PSU (1 OFF) WITH EXISTING 3kW RECTIFIERS (6 OFF) AND LPFG12-100S BATTERY STRINGS (5 OFF) FROM THE RACK AT G000F03. 2. INSTALL NEW OPTUS 27kW VERTIV PSU WITH NEW 3kW RECTIFIERS (6 OFF) AT G000F03. 3. INSTALL NEW LFeLi-48100ZN BATTERIES (5 OFF) IN RACK AT G000F03. VODAFONE DC POWER UPGRADE: 4. REMOVE EXISTING VODAFONE HUAWEI PSU (1 OFF) WITH EXISTING 3kW RECTIFIERS (6 OFF) AND LPFG12-100S BATTERY STRINGS (5 OFF) FROM THE RACK AT G000F04. 5. INSTALL NEW VODAFONE 27kW VERTIV PSU WITH NEW 3kW RECTIFIERS (6 OFF) AT G000F04. 6. INSTALL NEW LFeLi-48100ZN BATTERIES (5 OFF) IN RACK AT G000F04.
C36: Are any new circuit breakers required? | M36: No | S36: Yes
C38: Details | E38: REFER iDCDP LAYOUT
C40: Proposed Circuit Breaker layout Power Supply 1
C42: Allocate equal number of positions for each operator + 4 positions for TXMN
C44: Position | H44: 1 | I44: 2 | J44: 3 | K44: 4 | L44: 5 | M44: 6 | N44: 7 | O44: 8 | P44: 9 | Q44: 10 | R44: 11 | S44: 12
C45: Size
C46: Allocation
C48: Position | H48: 13 | I48: 14 | J48: 15 | K48: 16 | L48: 17 | M48: 18 | N48: 19 | O48: 20 | P48: 21 | Q48: 22 | R48: 23 | S48: 24
C49: Size
C50: Allocation
C52: Details
C54: Proposed Circuit Breaker layout Power Supply 2
C56: Allocate equal number of positions for each operator + 4 positions for TXMN
C58: Position | H58: 1 | I58: 2 | J58: 3 | K58: 4 | L58: 5 | M58: 6 | N58: 7 | O58: 8 | P58: 9 | Q58: 10 | R58: 11 | S58: 12
C59: Size
C60: Allocation
C62: Position | H62: 13 | I62: 14 | J62: 15 | K62: 16 | L62: 17 | M62: 18 | N62: 19 | O62: 20 | P62: 21 | Q62: 22 | R62: 23 | S62: 24
C63: Size
C64: Allocation
C66: Details
C68: Are any new DC cable lengths required? | M68: Yes | S68: Yes
C70: Details | E70: OPTUS: REUSE EXISTING OPTUS H&S 9/18 HYBRID CABLE (1 OFF) (LENGTH: 40m) AND SHARED H&S 9/18 HYBRID CABLE (1 OFF) (LENGTH: 40m) TO BE ALLOCATED TO OPTUS VODAFONE: REUSE EXISTING VODAFONE H&S 9/18 HYBRID CABLE (1 OFF) (LENGTH: 40m) AND INSTALL NEW H&S 9/18 (10mm2) HYBRID CABLES (1 OFF) (LENGTH: 40m) FOR VODAFONE
C72: Fill in the Scope of Works Summary box below with as much details as possible relating to proposed power system upgrade site works.
C74: OPTUS DC POWER UPGRADE: 1. REMOVE EXISTING OPTUS HUAWEI PSU (1 OFF) WITH EXISTING 3kW RECTIFIERS (6 OFF) AND LPFG12-100S BATTERY STRINGS (5 OFF) FROM THE RACK AT G000F03. 2. INSTALL NEW OPTUS 27kW VERTIV PSU WITH NEW 3kW RECTIFIERS (6 OFF) AT G000F03. 3. INSTALL NEW LFeLi-48100ZN BATTERIES (5 OFF) IN RACK AT G000F03. 4. REPLACE EXISTING 32A 1P CB (3 OFF) WITH NEW 40A 1P CB (3 OFF) FOR OPTUS PSU ON THE DISTRIBUTION BOARD. 5. OPTUS POWER TOOL V12.7 APPROVED. 6. DIVERSIFY Tx FEEDS OVER 2 PSUs. APDP FEED A ON OPTUS PSU-1-O. FEED B ON VODAFONE PSU-2-V. VODAFONE DC POWER UPGRADE: 7. REMOVE EXISTING VODAFONE HUAWEI PSU (1 OFF) WITH EXISTING 3kW RECTIFIERS (6 OFF) AND LPFG12-100S BATTERY STRINGS (5 OFF) FROM THE RACK AT G000F04. 8. INSTALL NEW VODAFONE 27kW VERTIV PSU WITH NEW 3kW RECTIFIERS (6 OFF) AT G000F04. 9. INSTALL NEW LFeLi-48100ZN BATTERIES (5 OFF) IN RACK AT G000F04. 10. REPLACE EXISTING 32A 1P CB (3 OFF) WITH NEW 40A 1P CB (3 OFF) FOR VODAFONE PSU ON THE DISTRIBUTION BOARD.
...

Sheet TX
B2: ='Document Control'!B2 -> OM34440 Optus Site Feasibility Report | I2: V | J2: ='Document Control'!C3 -> 5 | K2: Transmission Details Feasibility
B3: Site No. | D3: ='Cover Sheet'!G13 -> H8097 | G3: Site Name | J3: ='Cover Sheet'!G15 -> Austins Ferry
C5: NOTE: If you answer 'No' to the below question you are not required to complete any other information on this page, unless under instruction from Optus or performing a feasibility study.
C7: Are you performing a feasibility on the TX system? | S7: N/A
C9: Details
C13: Are you required to perform a feasibility study on the TX equipment?
C15: Details
C18: Existing Transmission Solution
C20: Suite Number | F20: Operator | H20: Vendor | L20: Bearing | N20: Height | P20: In Use | R20: Recovery Required | T20: Variation
C27: Details
C31: Proposed Transmission Solution
C33: Suite Number | F33: Operator | H33: Vendor | L33: Bearing | N33: Height | P33: In Use | R33: Recovery Required | T33: Variation
C40: Details
C44: Current JV Transmission Provider?
C46: EJV Transmission Provider?
C48: Is this an Optus EJV fibre site?
C50: Details
C53: Is there any equipment required to be recovered?
C55: Details
C58: Is there any unused or previously non recovered mW equipment that needs to be recovered either internally or on the tower?
C60: Details
C64: For EJV sites is Optus Fibre going to be provided?
C66: Details
C69: Is a leased line being used?
... C77: Details
C82: Existing MER TX Layout | Z82: LIBRARY
C84: Suite | M84: Suite | Y84: 44
Y85: 43 | Z85: ELTEK APDP
C86: 44 | M86: 44 | Y86: 42
C87: 43 | M87: 43 | Y87: 41
C88: 42 | M88: 42 | Y88: 40
C89: 41 | M89: 41 | Y89: 39
C90: 40 | M90: 40 | Y90: 38 | Z90: Ceragon IP10
C91: 39 | M91: 39 | Y91: 37
C92: 38 | M92: 38 | Y92: 36 | Z92: Aviat MSR
C93: 37 | M93: 37 | Y93: 35
C94: 36 | M94: 36 | Y94: 34
C95: 35 | M95: 35 | Y95: 33 | Z95: Ceragon IP20
C96: 34 | M96: 34 | Y96: 32
C97: 33 | M97: 33 | Y97: 31
...

Sheet Floor Layout
B2: ='Document Control'!B2 -> OM34440 Optus Site Feasibility Report | I2: V | J2: ='Document Control'!C3 -> 5 | K2: Floor Layout
B3: Site No. | D3: ='Cover Sheet'!G13 -> H8097 | G3: Site Name | J3: ='Cover Sheet'!G15 -> Austins Ferry
C5: NOTE: If you answer 'No' to the below question you are not required to complete any other information on this page, unless under instruction from Optus or performing a feasibility study.
C7: Are you performing a feasibility on the Floor Layout? | S7: Yes
C9: Details
C12: Are you required to perform a feasibility study on the shelter floor layout ? | T12: Yes
C14: Details
C17: Which side of the shelter are the feeders entering from? (Looking from door entry to rear wall) | T17: Other
C19: Details | E19: Rear wall
C21: Is any additional cable tray required? | T21: No
C23: Details
C25: If Yes, there adequate space for installation? | T25: N/A
C27: Details
C29: Is a second gland window required for feeders? | T29: No
C31: Details
C34: Existing Floor Layout
C38: Proposed Floor Layout | D38: Final Floor Layout
C42: Fill in the Scope of Works Summary box below with as much details as possible relating to your proposed floor layout site works.
C44: OPTUS NOTES: 1. REMOVE EXISTING OPTUS HUAWEI BBU AND DCDU FROM THE RACK AT G001F04. 2. INSTALL NEW 1 x ERICSSON BBU6672 FOR L7/NL9/L18/NL21/L26/NR35 IN RACK AT G001F04. 3. INSTALL NEW DCDU (1 OFF) TO POWER UP ERICSSON BBUs IN RACK AT G001F04. 4. ALL EXTERNAL ALARMS (ENVIRONMENTAL ETC) TO BE MIGRATED FROM UMTS BBU TO LTE/5G BBU, AS PER OPTUS STANDARDS, INCLUDING OM36991 RAN EQUIPMENT I&C STANDARDS. 5. ALL 3G CONTROLLED RET'S TO BE MIGRATED TO 4G/5G AS REQUIRED, ACCORDING TO OPTUS STANDARDS, INCLUDING OM38040 MIMO PORT PLUMBING BTS RET CONTROL DEPLOYMENT. 6. REMOVE ANY ON-SITE CCU'S AND CONVERT CCU CONTROLLED MHA'S TO BTS CONTROLLED 7. EXISTING KRONE PANEL TO BE UPGRADED TO RJ45 PATCH PANEL. INSTALL 1 x 6610 FOR PSU ALARM AT G000.F02. iDCDP NOTES: 8. REUSE EXISTING OPTUS 22-WAY LENMIC iDCDP (1 OFF) IN RACK AT G001F05. AND SWAP CBs ON PSU AND iDCDP AS PER LATEST GUIDELINE. HYBRID CABLE NOTES: 9. REUSE EXISTING OPTUS H&S 9/18 HYBRID CABLE (1 OFF) (LENGTH: 40m) AND SHARED H&S 9/18 HYBRID CABLE (1 OFF) (LENGTH: 40m) DC POWER UPGRADE: 10. REMOVE EXISTING OPTUS HUAWEI PSU (1 OFF) WITH EXISTING 3kW RECTIFIERS (6 OFF) AND LPFG12-100S BATTERY STRINGS (5 OFF) FROM THE RACK AT G000F03. 11. INSTALL NEW OPTUS 27kW VERTIV PSU WITH NEW 3kW RECTIFIERS (6 OFF) AT G000F03. 12. INSTALL NEW LFeLi-48100ZN BATTERIES (5 OFF) IN RACK AT G000F03. 13. REPLACE EXISTING 32A 1P CB (3 OFF) WITH NEW 40A 1P CB (3 OFF) FOR OPTUS PSU ON THE DISTRIBUTION BOARD. 14. OPTUS POWER TOOL V12.7 APPROVED. 15. DIVERSIFY Tx FEEDS OVER 2 PSUs. APDP FEED A ON OPTUS PSU-1-O. FEED B ON VODAFONE PSU-2-V. AC POWER UPGRADE: 16. EXISTING OPTUS 50A THREE PHASE POWER SUPPLY IS SUFFICIENT FOR THE PROPOSED UPGRADE. VODAFONE NOTES: 17. REMOVE EXISTING VODAFONE HUAWEI BBU AND DCDU FROM THE RACK AT G001F02. 18. INSTALL NEW NOKIA AIRSCALE/AMID CHASIS 1 OFF WITH SUITABLE BB CARDS AS PER EBP IN RACK AT G001F02. 19. NOKIA AIRSCALE SHALL BE POWER UP VIA VODAFONE PSU IN RACK AT G000F04. 20. NOKIA TX ROUTER TO BE RELOACTED FROM RU7 TO RU18 OR HIGHER POSTION AT G000F02. iDCDP NOTES: 21. REUSE EXISTING VODAFONE 22-WAY LENMIC iDCDP (1 OFF) IN RACK AT G001F05. AND SWAP CBs ON PSU AND iDCDP AS PER LATEST GUIDELINE. HYBRID CABLE NOTES: 22. REUSE EXISTING VODAFONE H&S 9/18 HYBRID CABLE (1 OFF) (LENGTH: 40m) AND INSTALL NEW H&S 9/18 (10mm2) HYBRID CABLES (1 OFF) (LENGTH: 40m) DC POWER UPGRADE: 23. REMOVE EXISTING VODAFONE HUAWEI PSU (1 OFF) WITH EXISTING 3kW RECTIFIERS (6 OFF) AND LPFG12-100S BATTERY STRINGS (5 OFF) FROM THE RACK AT G000F04. 24. INSTALL NEW VODAFONE 27kW VERTIV PSU WITH NEW 3kW RECTIFIERS (6 OFF) AT G000F04. 25. INSTALL NEW LFeLi-48100ZN BATTERIES (5 OFF) IN RACK AT G000F04. 26. REPLACE EXISTING 32A 1P CB (3 OFF) WITH NEW 40A 1P CB (3 OFF) FOR VODAFONE PSU ON THE DISTRIBUTION BOARD.
C50: Information will be automatically generated to the IC Works Summary tab
C52: Page Completed | H52: Yes | M52: By Whom | Q52: SARAVANAN S
C54: Company | H54: ALL TELECOS | M54: Date | Q54: 45913

Sheet Antenna System
B2: ='[1]Document Control'!B2 -> OM34440 Optus Site Feasibility Report | I2: V | J2: ='[1]Document Control'!C3 -> 5 | K2: Antenna System
B3: Site No. | D3: ='[1]Cover Sheet'!G13 -> H8097 | G3: Site Name | I3: ='[1]Cover Sheet'!G15 -> Austins Ferry
C5: NOTE: If you answer 'No' to the below question you are not required to complete any other information on this page, unless under instruction from Optus or performing a feasibility study.
C7: Have you completed antenna system site works?
C9: Existing Antenna System
C11: Details | E11: Existing shared 1x 12p large antenna
C14: Sector 1
C15: Antenna Number
C16: Antenna Model | H16: Huawei ASI4517R1
C17: Antenna Details | H17: 11-J
C18: Port Number | H18: Port 1&2 | I18: Port 3&4 | J18: Port 5&6 | K18: Port 7&8 | L18: Port 9&10 | M18: Port 11&12 | Q18: Port 1&2 | R18: Port 3&4 | S18: Port 5&6 | T18: Port 7&8 | U18: Port 9&10 | V18: Port 11&12
C19: Frequency | H19: 850/900 | I19: 700/900 | J19: 1800/2100 | K19: 1800/2100 | L19: 18/21/26 | M19: 18/21/26
C20: Carrier Using Ports | H20: Voda | I20: Optus | J20: Voda | K20: Voda | L20: Optus | M20: Optus
C21: Orientation (degrees) | H21: 0
C22: Electrical Down Tilt (degrees) | H22: 2 | I22: 2 | J22: 2 | K22: 2 | L22: 2 | M22: 2
C23: Mechanical Down Tilt | H23: 0
C24: Mounting Height (m) - AGL | H24: 23.1
C25: Coordinates (Easting, Northing) | H25: 55 | 520051 | 5263789
C26: RET Enabled on Antenna | H26: Yes | I26: Yes | J26: Yes | K26: Yes | L26: Yes | M26: Yes
C27: Feeder Type and Size
C28: Feeder Length (metres)
C29: Hybrid Cable (DC&Fibre) | H29: Yes | I29: Yes | J29: Yes | K29: Yes | L29: Yes | M29: Yes
C31: Antenna Number | H31: Antenna 3 | Q31: Antenna 4
C32: Antenna Model
C33: Antenna Details
C34: Port Number | H34: Port 1&2 | I34: Port 3&4 | J34: Port 5&6 | K34: Port 7&8 | L34: Port 9&10 | M34: Port 11&12 | Q34: Port 1&2 | R34: Port 3&4 | S34: Port 5&6 | T34: Port 7&8 | U34: Port 9&10 | V34: Port 11&12
C35: Frequency
C36: Carrier Using Ports
C37: Orientation (degrees)
C38: Electrical Down Tilt (degrees)
C39: Mechanical Down Tilt
C40: Mounting Height (m) - AGL
C41: Coordinates (Easting, Northing)
C42: RET Enabled on Antenna
C43: Feeder Type and Size
C44: Feeder Length (metres)
C45: Hybrid Cable (DC&Fibre)
C47: Sector 2
C48: Antenna Number
C49: Antenna Model | H49: Huawei ASI4517R1
...

Sheet Photos
B2: ='Document Control'!B2 -> OM34440 Optus Site Feasibility Report | I2: V | J2: ='Document Control'!C3 -> 5 | K2: Photos Existing
B3: Site No. | D3: ='Cover Sheet'!G13 -> H8097 | G3: Site Name | I3: ='Cover Sheet'!G15 -> Austins Ferry
C5: NOTE: If you answer 'No' to the below question you are not required to complete any other information on this page, unless under instruction from Optus or performing a feasibility study.
C7: Are you performing a feasibility which requires photos to be taken? | S7: Yes
C9: Details
C12: Naming Convention to be used explicitly below. If more than 1 photo taken of an item then up the end number
C13: External Photos
C15: Photo Name Required | J15: Comments | S15: Supplied
C16: SiteID_ShelterExt(N,E,S,W) | J16: The pictures must show the shelter/ OOC from NESW directions including the compound | S16: Yes
C17: SiteID_Tower | J17: Tower including new Feeders, MHA’s from ground level from NESW | S17: Yes
C18: SiteID_MastheadExt | J18: Includes MHA, Antenna cluster from ground level zoomed x10 from NESW | S18: Yes
C19: SiteID_ShelterGlandEntryExternal | J19: Gantry containing feeders entering the shelter gland window, taken from most suitable location | S19: Yes
C20: SiteID_EarthBarTowerBase | J20: Earth bar connections base of tower | S20: Yes
C21: SiteID_EarthBarTowerTop | J21: Earth bar connections top of tower | S21: No
C22: SiteID_EarthBarShelter | J22: Earth bar connections cable entry window outside of shelter | S22: Yes
C23: SiteID_EarthExtMisc | J23: Earth connections for any installed equipment on tower/pole | S23: No
C24: SiteID_HardwareExt | J24: Close ups of each installed piece of equipment (antennae, dish, MHA, diplexer etc | S24: Yes
C25: SiteID_LabelsExt | J25: Close ups of all labelling – in particular the base band cable label | S25: Yes
C27: Internal Photos
C29: Photo Name Required | J29: Comments | S29: Supplied
C30: SiteID_FloorLayout | J30: Floor Layout Taken from Entry door or open area showing as much of the internal hardware inside the shelter as possible including the new BTS using a wide angle lens | S30: Yes
C31: SiteID_BTSOverview | J31: Shows clusters of BTS as installed | S31: Yes
C32: SiteID_BTS_(Carrier,Freq) | J32: Shows detailed overview picture of BTS | S32: Yes
C33: SiteID_BTS_(Carrier,Freq) | J33: Shows detailed overview picture of BTS | S33: Yes
C34: SiteID_BTS_(Carrier,Freq) | J34: Shows detailed overview picture of BTS | S34: Yes
C35: SiteID_BTS_(Carrier,Freq) | J35: Shows detailed overview picture of BTS | S35: Yes
C36: SiteID_MER | J36: Entire Miscellaneous Equipment Rack must be clear enough to see new Transmission radio card or mux where added | S36: Yes
C37: SiteID_SkinnyMER | J37: Entire Miscellaneous Equipment Rack must be clear enough to see new Transmission radio card or mux where added | S37: Yes
C38: SiteID_Krone | J38: Overview of entire Krone’s showing new E1’s alarms etc where added. Must be clear enough to read when zoomed | S38: Yes
C39: SiteID_KroneRear | J39: Shows rear of Krone cabling proving neat and functional for maintenance | S39: No
C40: SiteID_RFTails | J40: Entire tails from BTS to Feeder connection point | S40: Yes
... C48: Site ID_ RETACU | J48: RET/MHA Control Unit | S48: N/A
C50: ACMA Photos (these need to be included in the Deployment Code Folder)
C52: Photo Name Required | J52: Comments | S52: Supplied
C53: SiteID_SiteEntranceLabel | J53: RF warning label on Door/Hatch/Gate entrance etc restricting access to shelter or antennas. | S53: Yes
C54: SiteID_NSASiteNumber | J54: RFNSA NSA label showing number, take an overview photo if location not obvious | S54: Yes
C55: SiteID_RF HazardSign | J55: Should be located next to the Entrance label | S55: Yes
C56: SiteID_AntennaLabels | J56: Yellow Radiation warning label on back of antennas | S56: Yes
C57: SiteID_AntennaAccessRestriction | J57: Do Not Climb Label placed at the bottom of antenna poles | S57: Yes
C58: SiteID_AntennaCluster(S1-6) | J58: Taken in front of each antenna or cluster | S58: Yes
...

Sheet Document Control
B2: OM34440 Optus Site Feasibility Report | E2: Document Control
B3: V | C3: 5
B5: Version | C5: Amendment | F5: Section | G5: Date | H5: Author
B6: 1 | C6: Document compilation. | F6: All | G6: 40625 | H6: Stuart Leslie
B7: 2 | C7: Complete overhaul converted to excel format, feasibility and Acceptance site folder. | F7: All | G7: 40675 | H7: Stuart Leslie
B8: 2a | C8: Antenna and SAE page updates. Added Scope of Works Summary page at end. | F8: All | G8: 40679 | H8: Stuart Leslie
B9: 3 | C9: Updated Plumbing template, added feasibility photo tab, included BOM and BOQ, Included summary tab | F9: All | G9: 40678 | H9: Paul Tremlett NSN
B10: 3a | C10: Combined Pauls changes above into version 2a | F10: All | G10: 40680 | H10: Stuart Leslie
B11: 3b | C11: Added MER tab and overall fixes | F11: All | G11: 40682 | H11: Stuart Leslie
B12: 3c | C12: Overall update and alignment | F12: All | G12: 40683 | H12: Paul Tremlett NSN
B13: 3c-1 | C13: Minor updates to format, DC power and BOM and cover sheet | F13: All | G13: 40688 | H13: Paul Tremlett NSN
B14: 3d | C14: Design tab, Attachments comment, Final Antennas System table amalgamated as Proposed/ Final, 3G Call testing updated for 3 Sectors, User Guide added. | F14: All | G14: 40737 | H14: Stuart Leslie
B15: 3e | C15: Total revision simplified complete structure and overall technicality | F15: All | G15: 40772 | H15: Stuart Leslie
B16: 3f | C16: updated BTS, Antennas System and RF plumbing tabs with more detail. | F16: BTS, Ant Sys & RF | G16: 40777 | H16: Stuart Leslie
B17: 3g | C17: Added Power Supply C/B requirements and DC feed lengths. Added Tail requirement and lengths to Details box in Antennas tab. | F17: BTS, Ant Sys | G17: 40787 | H17: Stuart Leslie
B18: 3h | C18: Changed SAED coordinates from AGD66 to GDA94. Documents acceptance 3G Commissioning docs. Corrected MW acceptance visibility, Antenna System tab-added Feeder Make. Site Access-Delivery questions added. Floor Layout questions | F18: SAE tabs, Doc Accept, Ant Sys, Site Access ,Floor Layout | G18: 40793 | H18: Stuart Leslie
B19: 3i | C19: Document overhaul, Power Calculator updated to support LTE, 3G Call testing updated to support 6 sectors. Added 4G Call testing tab. | F19: All | G19: 41037 | H19: Stuart Leslie
B20: 3j | C20: 3G Call testing modified to allow voice on carriers F2-F4 also. Total overhaul for Jve.2G Call testing Emergency numbers require sector only not per TRX. | F20: All | G20: 41059 | H20: Stuart Leslie- Mark Sirotti
B21: 3k | C21: 2G Call testing Emergency numbers require sector only not per TRX. Full upgrade for EJV requirement plus U900 LTE Projects. | F21: All | G21: 41123 | H21: Stuart Leslie
... B24: 3n | C24: replaced OHS tab with new WHS tab, added new BTSs into power calcs tab, updated antenna scenarios for Leyland project, general update for Leyland | F24: Power Calcs, WHS, Antenna | G24: 41668 | H24: Clyde King
B25: 4 | C25: Amalgamating new WHS form, previous OM and new updates re: Leyland, including: - fields for additional antennas and antenna coordinates - air can, efan & AC supply details updated - setting eJV-related fields to 'N/A' - field for nominating which BTS will control the RET - cleaning up drop-down lists - general tidy up and fixing up of cell references etc - replaced EME Forms A & B with updated forms | F25: Various | G25: 41680 | H25: Clyde King
B26: 5 | C26: Removed Form A and B Removed WHS tabs Reformated document Amended IC Works Summary Added Power Calculation Summary Report into DC Tab | F26: All | G26: 42289 | H26: Sokchea Bin

Sheet Data
A1: OM34440 Optus Site Feasibility Report | D1: DATA
A2: V | B2: ='Document Control'!C3 -> 5
A4: Yes/No | B4: WHS ratings | C4: Structure Type | D4: Structure Type | E4: Green | F4: Mount | G4: New | H4: MER | I4: Call | J4: Shelter Material | K4: Feeder location | L4: Lead Site | M4: Equipment Enclosure Type | N4: Hardware Vendor | O4: Cabinet | P4: Technology | Q4: Band1 | R4: Band | S4: Operator | T4: Transmission Type | U4: DC Vendor | V4: Quantity | W4: Transmission Make | X4: Landlord | Y4: Equipment Enclosure Type | Z4: Breaker allocation | AA4: Leadoperator | AB4: PlanningArea | AC4: RAG | AD4: PlanningCategory | AE4: CADeploymentCategory | AF4: Timeframes | AG4: RFCarrier | AH4: Yes/No/Pass/Fail | AI4: antenna model | AJ4: Eeprom | AK4: MCF guidelines | AL4: TechBand
A5: Yes | B5: 1 | C5: Monopole | D5: Monopole | G5: New | J5: Sandwich Panel | K5: Left | L5: Optus | M5: Sandwich Panel Shelter | N5: NSN | O5: DBS3800 | P5: GSM | Q5: 700 | R5: 700 | S5: Optus | T5: Carrier Ethernet | U5: Eltek FP2 | V5: 1 | W5: Huawei CX600 | X5: Optus | Y5: Shelter - standard 7.5m | Z5: O | AA5: Optus | AB5: Residential | AC5: Red | AD5: Maintenance | AE5: Existing Site (Sect 7) | AF5: 3 weeks | AG5: Optus | AH5: Yes | AI5: Commscope RV4PX310R | AJ5: Standard site use - Version 81 (OPT-ECON81DC & OPT-ECON81AC) | AK5: Progress to "Del 2" | AL5: DE34 G900
A6: No | B6: 2 | C6: Lattice Tower | D6: Lattice Tower | E6: Greenfield | F6: Rack | G6: Upgrade | H6: MER | I6: New | J6: Brick | K6: Right | L6: Optus JVe | M6: Brick Shelter | N6: Huawei | O6: BTS3900 | P6: UMTS | Q6: 850 | R6: 700/2600 | S6: Voda | T6: IP | U6: Eltek FP1 | V6: 2 | W6: Alcatel 1662 Mux | X6: Vodafone | Y6: Shelter - large | Z6: V | AA6: Vodafone | AB6: Commercial | AC6: Amber | AD6: I-SEPP 'exempt development' | AE6: New Site (Sect 6) | AF6: 10 weeks | AG6: Voda | AH6: No | AI6: Commscope R2V4PX310R | AJ6: Hub site with Alcatel 1662 use - Version 82 (OPT-ECON82DC & OPT-ECON82AC) | AK6: Please complete "Form B" and escalate | AL6: Ultrasite G900
A7: N/A | B7: 3 | C7: Street Furniture | D7: Street Furniture | E7: Existing | F7: MER (Fill in MER Layout) | G7: Recovery | H7: Wall | I7: Upgraded | J7: Concrete | K7: Other | L7: VHA | M7: Outdoor | N7: Ericsson | O7: BTS3900L | P7: LTE | Q7: 900 | R7: 700/21/26 | S7: Telstra | T7: Hybrid IP&E1 | U7: Invensys | V7: 3 | W7: Alcatel 1642 Mux | X7: Telstra | Y7: Shelter - small | Z7: TX | AB7: Industrial | AC7: Green | AD7: I-SEPP 'complying development' | AE7: Not applicable (DA site Sect 1.4.2) | AF7: 3 months | AG7: Other | AH7: Pass | AI7: Commscope RVVPX310R | AJ7: Leave existing Eeprom | AL7: Flexi G900
B8: 4 | C8: Rooftop | D8: Rooftop | F8: Wall Mount | G8: Relocation | H8: Other | I8: N/A | J8: Other | K8: N/A | L8: Voda JVe | M8: In Built | N8: N/A | O8: BTS3900L-C | P8: Other | Q8: 700/850 | R8: 700/2100 | S8: Other | T8: E1 | U8: Hawker | V8: 4 | W8: Aviat MSR | X8: Crown Castle | Y8: Equipment room | AB8: Area of ES | AD8: Vic telecode 'exempt' | AF8: 6 months | AG8: Spare | AH8: Fail | AI8: Commscope RRV4-65D-R6-EC | AJ8: N/A | AL8: DF34 G1800
B9: 5 | C9: Street Light | D9: Street Light | F9: Floor | G9: N/A | H9: N/A | J9: N/A | L9: Telstra | M9: Exchange | N9: Other | O9: Ultrasite | P9: N/A | Q9: 700/900 | R9: 850 | S9: N/A | T9: Satellite | U9: Ext Cabinet | V9: 5 | W9: Fujitsu FLM150E | X9: Other Master Site Agreement | Y9: Outdoor unit | AD9: DA / Planning Approval | AF9: 9 months | AG9: N/A | AH9: N/A | AI9: Prose 2G4WHF-01N | AL9: Ultrasite G1800
C10: N/A | D10: N/A | F10: Pole | G10: None | L10: Crown Castle | M10: DAS | O10: FCOA | Q10: 850/900 | R10: 900 | T10: Multidropped | U10: Ericsson BBS | V10: 6 | W10: Nortel OM1400 (Hub) | X10: Private Landlord | AI10: Tongyu T2004L6R021 | AL10: Flexi G1800
B11: Work Phase | C11: Other | D11: Other | F11: Other | L11: Other | M11: IBC | O11: ICS MER | Q11: 700/850/900 | R11: 1800 | T11: Other | U11: Other | V11: 7 | W11: NSN Flexihopper MW | X11: Other | AI11: other (provide detail below) | AL11: Ultrasite U900
B12: Inspection | F12: Other | M12: Street furniture | O12: Eltek MER | Q12: 1800 | R12: 2100 | T12: N/A | U12: N/A | V12: 8 | W12: FBX (Hubs for STM4) | X12: N/A | AL12: Flexi U900
B13: Build Phase | F13: Other | M13: Equipment Room | O13: Other | Q13: 2100 | R13: 2300 | V13: 9 | W13: MNI MW | X13: Road Authority | AL13: Multi Radio U900
B14: Installation/Commissioning | F14: Other | M14: Other | O14: N/A | Q14: 2300 | R14: 2600 | V14: 10 | W14: NSN DMR MW | X14: Local Council | AL14: Ultrasite U2100
B15: Maintenance | F15: Other | M15: N/A | Q15: 2600 | R15: 700/900 | V15: 11 | W15: Satellite Gear | AL15: Flexi U2100
F16: Other | Q16: 1800/2100 | R16: 850/900 | V16: 12 | W16: Cisco Router | AL16: DBS 3800 U900
B17: Heirarchy of Control | F17: Other | Q17: 1800/2300 | R17: 1800/2300 | V17: 13 | W17: Ericsson 301 | AL17: BTS3900 U900
B18: 1- Elimination | F18: Other | Q18: 2300/2600 | R18: 18/21/23 | V18: 14 | W18: Ericsson 601 | AL18: BTS3900L U900
B19: 2 - Isolation/Substitution | F19: Other | Q19: 18/21/23 | R19: 1800/2600 | V19: Other | W19: Ceragon 1500HP | AL19: DBS 3800 U2100
Q20: 18/21/26 | R20: 18/21/26 | V20: N/A | W20: Other | AL20: BTS3900 U2100
Q21: 18/23/26 | R21: 18/21/23/26 | W21: N/A | AL21: BTS3900L U2100
Q22: 21/23/26 | R22: 2300/2600 | AL22: BTS3900L G900
Q23: 18/21/23/26 | R23: 2100/2300 | AL23: BTS3900L G1800
Q24: Other | R24: Other | AL24: BTS3900
Q25: N/A | R25: N/A | AL25: N/A
Q26: 1800/2600 | AL26: Other
Q27: 2100/2300
Q28: 2100/2600
